2025-03-10 01:18:18,377 - db_handler - ERROR - Database connection error: (pymysql.err.OperationalError) (1049, "Unknown database 'data_db'")
(Background on this error at: https://sqlalche.me/e/14/e3q8)
Traceback (most recent call last):
  File "/Users/siddharthamahakur/PycharmProjects/SparkETLMaster/.venv/lib/python3.9/site-packages/sqlalchemy/engine/base.py", line 3371, in _wrap_pool_connect
    return fn()
  File "/Users/siddharthamahakur/PycharmProjects/SparkETLMaster/.venv/lib/python3.9/site-packages/sqlalchemy/pool/base.py", line 327, in connect
    return _ConnectionFairy._checkout(self)
  File "/Users/siddharthamahakur/PycharmProjects/SparkETLMaster/.venv/lib/python3.9/site-packages/sqlalchemy/pool/base.py", line 894, in _checkout
    fairy = _ConnectionRecord.checkout(pool)
  File "/Users/siddharthamahakur/PycharmProjects/SparkETLMaster/.venv/lib/python3.9/site-packages/sqlalchemy/pool/base.py", line 493, in checkout
    rec = pool._do_get()
  File "/Users/siddharthamahakur/PycharmProjects/SparkETLMaster/.venv/lib/python3.9/site-packages/sqlalchemy/pool/impl.py", line 146, in _do_get
    self._dec_overflow()
  File "/Users/siddharthamahakur/PycharmProjects/SparkETLMaster/.venv/lib/python3.9/site-packages/sqlalchemy/util/langhelpers.py", line 70, in __exit__
    compat.raise_(
  File "/Users/siddharthamahakur/PycharmProjects/SparkETLMaster/.venv/lib/python3.9/site-packages/sqlalchemy/util/compat.py", line 211, in raise_
    raise exception
  File "/Users/siddharthamahakur/PycharmProjects/SparkETLMaster/.venv/lib/python3.9/site-packages/sqlalchemy/pool/impl.py", line 143, in _do_get
    return self._create_connection()
  File "/Users/siddharthamahakur/PycharmProjects/SparkETLMaster/.venv/lib/python3.9/site-packages/sqlalchemy/pool/base.py", line 273, in _create_connection
    return _ConnectionRecord(self)
  File "/Users/siddharthamahakur/PycharmProjects/SparkETLMaster/.venv/lib/python3.9/site-packages/sqlalchemy/pool/base.py", line 388, in __init__
    self.__connect()
  File "/Users/siddharthamahakur/PycharmProjects/SparkETLMaster/.venv/lib/python3.9/site-packages/sqlalchemy/pool/base.py", line 691, in __connect
    pool.logger.debug("Error on connect(): %s", e)
  File "/Users/siddharthamahakur/PycharmProjects/SparkETLMaster/.venv/lib/python3.9/site-packages/sqlalchemy/util/langhelpers.py", line 70, in __exit__
    compat.raise_(
  File "/Users/siddharthamahakur/PycharmProjects/SparkETLMaster/.venv/lib/python3.9/site-packages/sqlalchemy/util/compat.py", line 211, in raise_
    raise exception
  File "/Users/siddharthamahakur/PycharmProjects/SparkETLMaster/.venv/lib/python3.9/site-packages/sqlalchemy/pool/base.py", line 686, in __connect
    self.dbapi_connection = connection = pool._invoke_creator(self)
  File "/Users/siddharthamahakur/PycharmProjects/SparkETLMaster/.venv/lib/python3.9/site-packages/sqlalchemy/engine/create.py", line 574, in connect
    return dialect.connect(*cargs, **cparams)
  File "/Users/siddharthamahakur/PycharmProjects/SparkETLMaster/.venv/lib/python3.9/site-packages/sqlalchemy/engine/default.py", line 598, in connect
    return self.dbapi.connect(*cargs, **cparams)
  File "/Users/siddharthamahakur/PycharmProjects/SparkETLMaster/.venv/lib/python3.9/site-packages/pymysql/connections.py", line 361, in __init__
    self.connect()
  File "/Users/siddharthamahakur/PycharmProjects/SparkETLMaster/.venv/lib/python3.9/site-packages/pymysql/connections.py", line 669, in connect
    self._request_authentication()
  File "/Users/siddharthamahakur/PycharmProjects/SparkETLMaster/.venv/lib/python3.9/site-packages/pymysql/connections.py", line 979, in _request_authentication
    auth_packet = _auth.caching_sha2_password_auth(self, auth_packet)
  File "/Users/siddharthamahakur/PycharmProjects/SparkETLMaster/.venv/lib/python3.9/site-packages/pymysql/_auth.py", line 241, in caching_sha2_password_auth
    pkt = conn._read_packet()
  File "/Users/siddharthamahakur/PycharmProjects/SparkETLMaster/.venv/lib/python3.9/site-packages/pymysql/connections.py", line 775, in _read_packet
    packet.raise_for_error()
  File "/Users/siddharthamahakur/PycharmProjects/SparkETLMaster/.venv/lib/python3.9/site-packages/pymysql/protocol.py", line 219, in raise_for_error
    err.raise_mysql_exception(self._data)
  File "/Users/siddharthamahakur/PycharmProjects/SparkETLMaster/.venv/lib/python3.9/site-packages/pymysql/err.py", line 150, in raise_mysql_exception
    raise errorclass(errno, errval)
pymysql.err.OperationalError: (1049, "Unknown database 'data_db'")

The above exception was the direct cause of the following exception:

Traceback (most recent call last):
  File "/Users/siddharthamahakur/PycharmProjects/SparkETLMaster/storage/db_writer.py", line 25, in __init__
    Base.metadata.create_all(self.engine)  # Ensure tables exist
  File "/Users/siddharthamahakur/PycharmProjects/SparkETLMaster/.venv/lib/python3.9/site-packages/sqlalchemy/sql/schema.py", line 4930, in create_all
    bind._run_ddl_visitor(
  File "/Users/siddharthamahakur/PycharmProjects/SparkETLMaster/.venv/lib/python3.9/site-packages/sqlalchemy/engine/base.py", line 3237, in _run_ddl_visitor
    with self.begin() as conn:
  File "/Users/siddharthamahakur/PycharmProjects/SparkETLMaster/.venv/lib/python3.9/site-packages/sqlalchemy/engine/base.py", line 3153, in begin
    conn = self.connect(close_with_result=close_with_result)
  File "/Users/siddharthamahakur/PycharmProjects/SparkETLMaster/.venv/lib/python3.9/site-packages/sqlalchemy/engine/base.py", line 3325, in connect
    return self._connection_cls(self, close_with_result=close_with_result)
  File "/Users/siddharthamahakur/PycharmProjects/SparkETLMaster/.venv/lib/python3.9/site-packages/sqlalchemy/engine/base.py", line 96, in __init__
    else engine.raw_connection()
  File "/Users/siddharthamahakur/PycharmProjects/SparkETLMaster/.venv/lib/python3.9/site-packages/sqlalchemy/engine/base.py", line 3404, in raw_connection
    return self._wrap_pool_connect(self.pool.connect, _connection)
  File "/Users/siddharthamahakur/PycharmProjects/SparkETLMaster/.venv/lib/python3.9/site-packages/sqlalchemy/engine/base.py", line 3374, in _wrap_pool_connect
    Connection._handle_dbapi_exception_noconnection(
  File "/Users/siddharthamahakur/PycharmProjects/SparkETLMaster/.venv/lib/python3.9/site-packages/sqlalchemy/engine/base.py", line 2208, in _handle_dbapi_exception_noconnection
    util.raise_(
  File "/Users/siddharthamahakur/PycharmProjects/SparkETLMaster/.venv/lib/python3.9/site-packages/sqlalchemy/util/compat.py", line 211, in raise_
    raise exception
  File "/Users/siddharthamahakur/PycharmProjects/SparkETLMaster/.venv/lib/python3.9/site-packages/sqlalchemy/engine/base.py", line 3371, in _wrap_pool_connect
    return fn()
  File "/Users/siddharthamahakur/PycharmProjects/SparkETLMaster/.venv/lib/python3.9/site-packages/sqlalchemy/pool/base.py", line 327, in connect
    return _ConnectionFairy._checkout(self)
  File "/Users/siddharthamahakur/PycharmProjects/SparkETLMaster/.venv/lib/python3.9/site-packages/sqlalchemy/pool/base.py", line 894, in _checkout
    fairy = _ConnectionRecord.checkout(pool)
  File "/Users/siddharthamahakur/PycharmProjects/SparkETLMaster/.venv/lib/python3.9/site-packages/sqlalchemy/pool/base.py", line 493, in checkout
    rec = pool._do_get()
  File "/Users/siddharthamahakur/PycharmProjects/SparkETLMaster/.venv/lib/python3.9/site-packages/sqlalchemy/pool/impl.py", line 146, in _do_get
    self._dec_overflow()
  File "/Users/siddharthamahakur/PycharmProjects/SparkETLMaster/.venv/lib/python3.9/site-packages/sqlalchemy/util/langhelpers.py", line 70, in __exit__
    compat.raise_(
  File "/Users/siddharthamahakur/PycharmProjects/SparkETLMaster/.venv/lib/python3.9/site-packages/sqlalchemy/util/compat.py", line 211, in raise_
    raise exception
  File "/Users/siddharthamahakur/PycharmProjects/SparkETLMaster/.venv/lib/python3.9/site-packages/sqlalchemy/pool/impl.py", line 143, in _do_get
    return self._create_connection()
  File "/Users/siddharthamahakur/PycharmProjects/SparkETLMaster/.venv/lib/python3.9/site-packages/sqlalchemy/pool/base.py", line 273, in _create_connection
    return _ConnectionRecord(self)
  File "/Users/siddharthamahakur/PycharmProjects/SparkETLMaster/.venv/lib/python3.9/site-packages/sqlalchemy/pool/base.py", line 388, in __init__
    self.__connect()
  File "/Users/siddharthamahakur/PycharmProjects/SparkETLMaster/.venv/lib/python3.9/site-packages/sqlalchemy/pool/base.py", line 691, in __connect
    pool.logger.debug("Error on connect(): %s", e)
  File "/Users/siddharthamahakur/PycharmProjects/SparkETLMaster/.venv/lib/python3.9/site-packages/sqlalchemy/util/langhelpers.py", line 70, in __exit__
    compat.raise_(
  File "/Users/siddharthamahakur/PycharmProjects/SparkETLMaster/.venv/lib/python3.9/site-packages/sqlalchemy/util/compat.py", line 211, in raise_
    raise exception
  File "/Users/siddharthamahakur/PycharmProjects/SparkETLMaster/.venv/lib/python3.9/site-packages/sqlalchemy/pool/base.py", line 686, in __connect
    self.dbapi_connection = connection = pool._invoke_creator(self)
  File "/Users/siddharthamahakur/PycharmProjects/SparkETLMaster/.venv/lib/python3.9/site-packages/sqlalchemy/engine/create.py", line 574, in connect
    return dialect.connect(*cargs, **cparams)
  File "/Users/siddharthamahakur/PycharmProjects/SparkETLMaster/.venv/lib/python3.9/site-packages/sqlalchemy/engine/default.py", line 598, in connect
    return self.dbapi.connect(*cargs, **cparams)
  File "/Users/siddharthamahakur/PycharmProjects/SparkETLMaster/.venv/lib/python3.9/site-packages/pymysql/connections.py", line 361, in __init__
    self.connect()
  File "/Users/siddharthamahakur/PycharmProjects/SparkETLMaster/.venv/lib/python3.9/site-packages/pymysql/connections.py", line 669, in connect
    self._request_authentication()
  File "/Users/siddharthamahakur/PycharmProjects/SparkETLMaster/.venv/lib/python3.9/site-packages/pymysql/connections.py", line 979, in _request_authentication
    auth_packet = _auth.caching_sha2_password_auth(self, auth_packet)
  File "/Users/siddharthamahakur/PycharmProjects/SparkETLMaster/.venv/lib/python3.9/site-packages/pymysql/_auth.py", line 241, in caching_sha2_password_auth
    pkt = conn._read_packet()
  File "/Users/siddharthamahakur/PycharmProjects/SparkETLMaster/.venv/lib/python3.9/site-packages/pymysql/connections.py", line 775, in _read_packet
    packet.raise_for_error()
  File "/Users/siddharthamahakur/PycharmProjects/SparkETLMaster/.venv/lib/python3.9/site-packages/pymysql/protocol.py", line 219, in raise_for_error
    err.raise_mysql_exception(self._data)
  File "/Users/siddharthamahakur/PycharmProjects/SparkETLMaster/.venv/lib/python3.9/site-packages/pymysql/err.py", line 150, in raise_mysql_exception
    raise errorclass(errno, errval)
sqlalchemy.exc.OperationalError: (pymysql.err.OperationalError) (1049, "Unknown database 'data_db'")
(Background on this error at: https://sqlalche.me/e/14/e3q8)
