2025-03-10 01:00:13,401 - db_writer - ERROR - Error writing to MySQL: (1049, "Unknown database 'data_db'")
Traceback (most recent call last):
  File "/Users/siddharthamahakur/PycharmProjects/SparkETLMaster/storage/db_writer.py", line 11, in write_to_mysql
    conn = pymysql.connect(host=host, user=user, password=password, database=db)
  File "/Users/siddharthamahakur/PycharmProjects/SparkETLMaster/.venv/lib/python3.9/site-packages/pymysql/connections.py", line 361, in __init__
    self.connect()
  File "/Users/siddharthamahakur/PycharmProjects/SparkETLMaster/.venv/lib/python3.9/site-packages/pymysql/connections.py", line 669, in connect
    self._request_authentication()
  File "/Users/siddharthamahakur/PycharmProjects/SparkETLMaster/.venv/lib/python3.9/site-packages/pymysql/connections.py", line 979, in _request_authentication
    auth_packet = _auth.caching_sha2_password_auth(self, auth_packet)
  File "/Users/siddharthamahakur/PycharmProjects/SparkETLMaster/.venv/lib/python3.9/site-packages/pymysql/_auth.py", line 241, in caching_sha2_password_auth
    pkt = conn._read_packet()
  File "/Users/siddharthamahakur/PycharmProjects/SparkETLMaster/.venv/lib/python3.9/site-packages/pymysql/connections.py", line 775, in _read_packet
    packet.raise_for_error()
  File "/Users/siddharthamahakur/PycharmProjects/SparkETLMaster/.venv/lib/python3.9/site-packages/pymysql/protocol.py", line 219, in raise_for_error
    err.raise_mysql_exception(self._data)
  File "/Users/siddharthamahakur/PycharmProjects/SparkETLMaster/.venv/lib/python3.9/site-packages/pymysql/err.py", line 150, in raise_mysql_exception
    raise errorclass(errno, errval)
pymysql.err.OperationalError: (1049, "Unknown database 'data_db'")
